[2025-06-09T13:40:26.099+0000] {local_task_job_runner.py:120} INFO - ::group::Pre task execution logs
[2025-06-09T13:40:26.117+0000] {taskinstance.py:2076} INFO - Dependencies all met for dep_context=non-requeueable deps ti=<TaskInstance: kafka_pipeline_branching_dag.run_producer manual__2025-06-09T13:40:03.148309+00:00 [queued]>
[2025-06-09T13:40:26.122+0000] {taskinstance.py:2076} INFO - Dependencies all met for dep_context=requeueable deps ti=<TaskInstance: kafka_pipeline_branching_dag.run_producer manual__2025-06-09T13:40:03.148309+00:00 [queued]>
[2025-06-09T13:40:26.122+0000] {taskinstance.py:2306} INFO - Starting attempt 3 of 3
[2025-06-09T13:40:26.128+0000] {taskinstance.py:2330} INFO - Executing <Task(BashOperator): run_producer> on 2025-06-09 13:40:03.148309+00:00
[2025-06-09T13:40:26.132+0000] {logging_mixin.py:188} WARNING - /home/***/.local/lib/python3.12/site-packages/***/task/task_runner/standard_task_runner.py:61 DeprecationWarning: This process (pid=1421) is multi-threaded, use of fork() may lead to deadlocks in the child.
[2025-06-09T13:40:26.133+0000] {standard_task_runner.py:63} INFO - Started process 1422 to run task
[2025-06-09T13:40:26.132+0000] {standard_task_runner.py:90} INFO - Running: ['***', 'tasks', 'run', 'kafka_pipeline_branching_dag', 'run_producer', 'manual__2025-06-09T13:40:03.148309+00:00', '--job-id', '10', '--raw', '--subdir', 'DAGS_FOLDER/kafka_pipeline_dag.py', '--cfg-path', '/tmp/tmp9rnlo_rq']
[2025-06-09T13:40:26.134+0000] {standard_task_runner.py:91} INFO - Job 10: Subtask run_producer
[2025-06-09T13:40:26.156+0000] {task_command.py:426} INFO - Running <TaskInstance: kafka_pipeline_branching_dag.run_producer manual__2025-06-09T13:40:03.148309+00:00 [running]> on host 4e91ff50f4f4
[2025-06-09T13:40:26.194+0000] {taskinstance.py:2648} INFO - Exporting env vars: AIRFLOW_CTX_DAG_OWNER='***' AIRFLOW_CTX_DAG_ID='kafka_pipeline_branching_dag' AIRFLOW_CTX_TASK_ID='run_producer' AIRFLOW_CTX_EXECUTION_DATE='2025-06-09T13:40:03.148309+00:00' AIRFLOW_CTX_TRY_NUMBER='3' AIRFLOW_CTX_DAG_RUN_ID='manual__2025-06-09T13:40:03.148309+00:00'
[2025-06-09T13:40:26.195+0000] {taskinstance.py:430} INFO - ::endgroup::
[2025-06-09T13:40:26.202+0000] {subprocess.py:63} INFO - Tmp dir root location: /tmp
[2025-06-09T13:40:26.202+0000] {subprocess.py:75} INFO - Running command: ['/usr/bin/bash', '-c', 'python /opt/***/scripts/producer.py']
[2025-06-09T13:40:26.207+0000] {subprocess.py:86} INFO - Output:
[2025-06-09T13:40:26.247+0000] {subprocess.py:93} INFO - python: can't open file '/opt/***/scripts/producer.py': [Errno 2] No such file or directory
[2025-06-09T13:40:26.250+0000] {subprocess.py:97} INFO - Command exited with return code 2
[2025-06-09T13:40:26.250+0000] {taskinstance.py:441} INFO - ::group::Post task execution logs
[2025-06-09T13:40:26.256+0000] {taskinstance.py:2905} ERROR - Task failed with exception
Traceback (most recent call last):
  File "/home/airflow/.local/lib/python3.12/site-packages/airflow/models/taskinstance.py", line 465, in _execute_task
    result = _execute_callable(context=context, **execute_callable_kwargs)
             ^^^^^^^^^^^^^^^^^^^^^^^^^^^^^^^^^^^^^^^^^^^^^^^^^^^^^^^^^^^^^
  File "/home/airflow/.local/lib/python3.12/site-packages/airflow/models/taskinstance.py", line 432, in _execute_callable
    return execute_callable(context=context, **execute_callable_kwargs)
           ^^^^^^^^^^^^^^^^^^^^^^^^^^^^^^^^^^^^^^^^^^^^^^^^^^^^^^^^^^^^
  File "/home/airflow/.local/lib/python3.12/site-packages/airflow/models/baseoperator.py", line 400, in wrapper
    return func(self, *args, **kwargs)
           ^^^^^^^^^^^^^^^^^^^^^^^^^^^
  File "/home/airflow/.local/lib/python3.12/site-packages/airflow/operators/bash.py", line 243, in execute
    raise AirflowException(
airflow.exceptions.AirflowException: Bash command failed. The command returned a non-zero exit code 2.
[2025-06-09T13:40:26.258+0000] {taskinstance.py:1206} INFO - Marking task as FAILED. dag_id=kafka_pipeline_branching_dag, task_id=run_producer, run_id=manual__2025-06-09T13:40:03.148309+00:00, execution_date=20250609T134003, start_date=20250609T134026, end_date=20250609T134026
[2025-06-09T13:40:26.263+0000] {standard_task_runner.py:110} ERROR - Failed to execute job 10 for task run_producer (Bash command failed. The command returned a non-zero exit code 2.; 1422)
[2025-06-09T13:40:26.272+0000] {local_task_job_runner.py:240} INFO - Task exited with return code 1
[2025-06-09T13:40:26.283+0000] {taskinstance.py:3498} INFO - 0 downstream tasks scheduled from follow-on schedule check
[2025-06-09T13:40:26.285+0000] {local_task_job_runner.py:222} INFO - ::endgroup::
