[2025-06-10T12:35:13.997+0000] {local_task_job_runner.py:120} INFO - ::group::Pre task execution logs
[2025-06-10T12:35:14.031+0000] {taskinstance.py:2076} INFO - Dependencies all met for dep_context=non-requeueable deps ti=<TaskInstance: kafka_pipeline_branching_dag.run_consumer scheduled__2025-06-10T12:25:00+00:00 [queued]>
[2025-06-10T12:35:14.037+0000] {taskinstance.py:2076} INFO - Dependencies all met for dep_context=requeueable deps ti=<TaskInstance: kafka_pipeline_branching_dag.run_consumer scheduled__2025-06-10T12:25:00+00:00 [queued]>
[2025-06-10T12:35:14.037+0000] {taskinstance.py:2306} INFO - Starting attempt 2 of 3
[2025-06-10T12:35:14.046+0000] {taskinstance.py:2330} INFO - Executing <Task(BashOperator): run_consumer> on 2025-06-10 12:25:00+00:00
[2025-06-10T12:35:14.057+0000] {logging_mixin.py:188} WARNING - /home/***/.local/lib/python3.12/site-packages/***/task/task_runner/standard_task_runner.py:61 DeprecationWarning: This process (pid=10488) is multi-threaded, use of fork() may lead to deadlocks in the child.
[2025-06-10T12:35:14.059+0000] {standard_task_runner.py:63} INFO - Started process 10491 to run task
[2025-06-10T12:35:14.055+0000] {standard_task_runner.py:90} INFO - Running: ['***', 'tasks', 'run', 'kafka_pipeline_branching_dag', 'run_consumer', 'scheduled__2025-06-10T12:25:00+00:00', '--job-id', '40', '--raw', '--subdir', 'DAGS_FOLDER/kafka_pipeline_dag.py', '--cfg-path', '/tmp/tmp_l9dfndw']
[2025-06-10T12:35:14.060+0000] {standard_task_runner.py:91} INFO - Job 40: Subtask run_consumer
[2025-06-10T12:35:14.111+0000] {task_command.py:426} INFO - Running <TaskInstance: kafka_pipeline_branching_dag.run_consumer scheduled__2025-06-10T12:25:00+00:00 [running]> on host 4e91ff50f4f4
[2025-06-10T12:35:14.171+0000] {taskinstance.py:2648} INFO - Exporting env vars: AIRFLOW_CTX_DAG_OWNER='***' AIRFLOW_CTX_DAG_ID='kafka_pipeline_branching_dag' AIRFLOW_CTX_TASK_ID='run_consumer' AIRFLOW_CTX_EXECUTION_DATE='2025-06-10T12:25:00+00:00' AIRFLOW_CTX_TRY_NUMBER='2' AIRFLOW_CTX_DAG_RUN_ID='scheduled__2025-06-10T12:25:00+00:00'
[2025-06-10T12:35:14.172+0000] {taskinstance.py:430} INFO - ::endgroup::
[2025-06-10T12:35:14.180+0000] {subprocess.py:63} INFO - Tmp dir root location: /tmp
[2025-06-10T12:35:14.181+0000] {subprocess.py:75} INFO - Running command: ['/usr/bin/bash', '-c', 'timeout 300 python /opt/***/kafka_client/consumer.py > /opt/***/logs/consumer_output.log 2>&1']
[2025-06-10T12:35:14.188+0000] {subprocess.py:86} INFO - Output:
[2025-06-10T12:40:14.215+0000] {subprocess.py:97} INFO - Command exited with return code 124
[2025-06-10T12:40:14.222+0000] {taskinstance.py:441} INFO - ::group::Post task execution logs
[2025-06-10T12:40:14.270+0000] {taskinstance.py:2905} ERROR - Task failed with exception
Traceback (most recent call last):
  File "/home/airflow/.local/lib/python3.12/site-packages/airflow/models/taskinstance.py", line 465, in _execute_task
    result = _execute_callable(context=context, **execute_callable_kwargs)
             ^^^^^^^^^^^^^^^^^^^^^^^^^^^^^^^^^^^^^^^^^^^^^^^^^^^^^^^^^^^^^
  File "/home/airflow/.local/lib/python3.12/site-packages/airflow/models/taskinstance.py", line 432, in _execute_callable
    return execute_callable(context=context, **execute_callable_kwargs)
           ^^^^^^^^^^^^^^^^^^^^^^^^^^^^^^^^^^^^^^^^^^^^^^^^^^^^^^^^^^^^
  File "/home/airflow/.local/lib/python3.12/site-packages/airflow/models/baseoperator.py", line 400, in wrapper
    return func(self, *args, **kwargs)
           ^^^^^^^^^^^^^^^^^^^^^^^^^^^
  File "/home/airflow/.local/lib/python3.12/site-packages/airflow/operators/bash.py", line 243, in execute
    raise AirflowException(
airflow.exceptions.AirflowException: Bash command failed. The command returned a non-zero exit code 124.
[2025-06-10T12:40:14.278+0000] {taskinstance.py:1206} INFO - Marking task as UP_FOR_RETRY. dag_id=kafka_pipeline_branching_dag, task_id=run_consumer, run_id=scheduled__2025-06-10T12:25:00+00:00, execution_date=20250610T122500, start_date=20250610T123514, end_date=20250610T124014
[2025-06-10T12:40:14.299+0000] {standard_task_runner.py:110} ERROR - Failed to execute job 40 for task run_consumer (Bash command failed. The command returned a non-zero exit code 124.; 10491)
[2025-06-10T12:40:14.346+0000] {local_task_job_runner.py:240} INFO - Task exited with return code 1
[2025-06-10T12:40:14.366+0000] {local_task_job_runner.py:222} INFO - ::endgroup::
