[2025-06-10T12:30:02.505+0000] {local_task_job_runner.py:120} INFO - ::group::Pre task execution logs
[2025-06-10T12:30:02.543+0000] {taskinstance.py:2076} INFO - Dependencies all met for dep_context=non-requeueable deps ti=<TaskInstance: kafka_pipeline_branching_dag.run_consumer scheduled__2025-06-10T12:25:00+00:00 [queued]>
[2025-06-10T12:30:02.554+0000] {taskinstance.py:2076} INFO - Dependencies all met for dep_context=requeueable deps ti=<TaskInstance: kafka_pipeline_branching_dag.run_consumer scheduled__2025-06-10T12:25:00+00:00 [queued]>
[2025-06-10T12:30:02.554+0000] {taskinstance.py:2306} INFO - Starting attempt 1 of 3
[2025-06-10T12:30:02.572+0000] {taskinstance.py:2330} INFO - Executing <Task(BashOperator): run_consumer> on 2025-06-10 12:25:00+00:00
[2025-06-10T12:30:02.600+0000] {logging_mixin.py:188} WARNING - /home/***/.local/lib/python3.12/site-packages/***/task/task_runner/standard_task_runner.py:61 DeprecationWarning: This process (pid=10096) is multi-threaded, use of fork() may lead to deadlocks in the child.
[2025-06-10T12:30:02.588+0000] {standard_task_runner.py:90} INFO - Running: ['***', 'tasks', 'run', 'kafka_pipeline_branching_dag', 'run_consumer', 'scheduled__2025-06-10T12:25:00+00:00', '--job-id', '30', '--raw', '--subdir', 'DAGS_FOLDER/kafka_pipeline_dag.py', '--cfg-path', '/tmp/tmpe09r180b']
[2025-06-10T12:30:02.604+0000] {standard_task_runner.py:63} INFO - Started process 10098 to run task
[2025-06-10T12:30:02.605+0000] {standard_task_runner.py:91} INFO - Job 30: Subtask run_consumer
[2025-06-10T12:30:02.695+0000] {task_command.py:426} INFO - Running <TaskInstance: kafka_pipeline_branching_dag.run_consumer scheduled__2025-06-10T12:25:00+00:00 [running]> on host 4e91ff50f4f4
[2025-06-10T12:30:02.791+0000] {taskinstance.py:2648} INFO - Exporting env vars: AIRFLOW_CTX_DAG_OWNER='***' AIRFLOW_CTX_DAG_ID='kafka_pipeline_branching_dag' AIRFLOW_CTX_TASK_ID='run_consumer' AIRFLOW_CTX_EXECUTION_DATE='2025-06-10T12:25:00+00:00' AIRFLOW_CTX_TRY_NUMBER='1' AIRFLOW_CTX_DAG_RUN_ID='scheduled__2025-06-10T12:25:00+00:00'
[2025-06-10T12:30:02.791+0000] {taskinstance.py:430} INFO - ::endgroup::
[2025-06-10T12:30:02.802+0000] {subprocess.py:63} INFO - Tmp dir root location: /tmp
[2025-06-10T12:30:02.803+0000] {subprocess.py:75} INFO - Running command: ['/usr/bin/bash', '-c', 'timeout 300 python /opt/***/kafka_client/consumer.py > /opt/***/logs/consumer_output.log 2>&1']
[2025-06-10T12:30:02.827+0000] {subprocess.py:86} INFO - Output:
[2025-06-10T12:35:02.869+0000] {subprocess.py:97} INFO - Command exited with return code 124
[2025-06-10T12:35:02.878+0000] {taskinstance.py:441} INFO - ::group::Post task execution logs
[2025-06-10T12:35:02.940+0000] {taskinstance.py:2905} ERROR - Task failed with exception
Traceback (most recent call last):
  File "/home/airflow/.local/lib/python3.12/site-packages/airflow/models/taskinstance.py", line 465, in _execute_task
    result = _execute_callable(context=context, **execute_callable_kwargs)
             ^^^^^^^^^^^^^^^^^^^^^^^^^^^^^^^^^^^^^^^^^^^^^^^^^^^^^^^^^^^^^
  File "/home/airflow/.local/lib/python3.12/site-packages/airflow/models/taskinstance.py", line 432, in _execute_callable
    return execute_callable(context=context, **execute_callable_kwargs)
           ^^^^^^^^^^^^^^^^^^^^^^^^^^^^^^^^^^^^^^^^^^^^^^^^^^^^^^^^^^^^
  File "/home/airflow/.local/lib/python3.12/site-packages/airflow/models/baseoperator.py", line 400, in wrapper
    return func(self, *args, **kwargs)
           ^^^^^^^^^^^^^^^^^^^^^^^^^^^
  File "/home/airflow/.local/lib/python3.12/site-packages/airflow/operators/bash.py", line 243, in execute
    raise AirflowException(
airflow.exceptions.AirflowException: Bash command failed. The command returned a non-zero exit code 124.
[2025-06-10T12:35:02.951+0000] {taskinstance.py:1206} INFO - Marking task as UP_FOR_RETRY. dag_id=kafka_pipeline_branching_dag, task_id=run_consumer, run_id=scheduled__2025-06-10T12:25:00+00:00, execution_date=20250610T122500, start_date=20250610T123002, end_date=20250610T123502
[2025-06-10T12:35:03.003+0000] {standard_task_runner.py:110} ERROR - Failed to execute job 30 for task run_consumer (Bash command failed. The command returned a non-zero exit code 124.; 10098)
[2025-06-10T12:35:03.026+0000] {local_task_job_runner.py:240} INFO - Task exited with return code 1
[2025-06-10T12:35:03.077+0000] {taskinstance.py:3498} INFO - 0 downstream tasks scheduled from follow-on schedule check
[2025-06-10T12:35:03.080+0000] {local_task_job_runner.py:222} INFO - ::endgroup::
