[2025-06-08T13:38:18.368+0000] {local_task_job_runner.py:120} INFO - ::group::Pre task execution logs
[2025-06-08T13:38:18.386+0000] {taskinstance.py:2076} INFO - Dependencies all met for dep_context=non-requeueable deps ti=<TaskInstance: master_pipeline_with_es_guard.run_consumer manual__2025-06-08T13:37:49.721097+00:00 [queued]>
[2025-06-08T13:38:18.390+0000] {taskinstance.py:2076} INFO - Dependencies all met for dep_context=requeueable deps ti=<TaskInstance: master_pipeline_with_es_guard.run_consumer manual__2025-06-08T13:37:49.721097+00:00 [queued]>
[2025-06-08T13:38:18.390+0000] {taskinstance.py:2306} INFO - Starting attempt 2 of 2
[2025-06-08T13:38:18.398+0000] {taskinstance.py:2330} INFO - Executing <Task(BashOperator): run_consumer> on 2025-06-08 13:37:49.721097+00:00
[2025-06-08T13:38:18.402+0000] {logging_mixin.py:188} WARNING - /home/***/.local/lib/python3.12/site-packages/***/task/task_runner/standard_task_runner.py:61 DeprecationWarning: This process (pid=1453) is multi-threaded, use of fork() may lead to deadlocks in the child.
[2025-06-08T13:38:18.403+0000] {standard_task_runner.py:63} INFO - Started process 1454 to run task
[2025-06-08T13:38:18.402+0000] {standard_task_runner.py:90} INFO - Running: ['***', 'tasks', 'run', 'master_pipeline_with_es_guard', 'run_consumer', 'manual__2025-06-08T13:37:49.721097+00:00', '--job-id', '35', '--raw', '--subdir', 'DAGS_FOLDER/producer_dag.py', '--cfg-path', '/tmp/tmpli6hatm6']
[2025-06-08T13:38:18.404+0000] {standard_task_runner.py:91} INFO - Job 35: Subtask run_consumer
[2025-06-08T13:38:18.434+0000] {task_command.py:426} INFO - Running <TaskInstance: master_pipeline_with_es_guard.run_consumer manual__2025-06-08T13:37:49.721097+00:00 [running]> on host 5492e8ecb5c1
[2025-06-08T13:38:18.498+0000] {taskinstance.py:2648} INFO - Exporting env vars: AIRFLOW_CTX_DAG_OWNER='panshul' AIRFLOW_CTX_DAG_ID='master_pipeline_with_es_guard' AIRFLOW_CTX_TASK_ID='run_consumer' AIRFLOW_CTX_EXECUTION_DATE='2025-06-08T13:37:49.721097+00:00' AIRFLOW_CTX_TRY_NUMBER='2' AIRFLOW_CTX_DAG_RUN_ID='manual__2025-06-08T13:37:49.721097+00:00'
[2025-06-08T13:38:18.499+0000] {taskinstance.py:430} INFO - ::endgroup::
[2025-06-08T13:38:18.509+0000] {subprocess.py:63} INFO - Tmp dir root location: /tmp
[2025-06-08T13:38:18.510+0000] {subprocess.py:75} INFO - Running command: ['/usr/bin/bash', '-c', 'python /opt/***/kafka_client/consumer.py']
[2025-06-08T13:38:18.517+0000] {subprocess.py:86} INFO - Output:
[2025-06-08T13:38:20.102+0000] {subprocess.py:93} INFO - 2025-06-08 13:38:20,101 - INFO - ✅ spaCy model loaded successfully
[2025-06-08T13:38:20.124+0000] {subprocess.py:93} INFO - 2025-06-08 13:38:20,124 - INFO - ✅ Geolocator initialized
[2025-06-08T13:38:20.210+0000] {subprocess.py:93} INFO - 2025-06-08 13:38:20,210 - INFO - <BrokerConnection node_id=bootstrap-0 host=localhost:9092 <connecting> [IPv6 ('::1', 9092, 0, 0)]>: connecting to localhost:9092 [('::1', 9092, 0, 0) IPv6]
[2025-06-08T13:38:20.211+0000] {subprocess.py:93} INFO - 2025-06-08 13:38:20,211 - INFO - Probing node bootstrap-0 broker version
[2025-06-08T13:38:20.214+0000] {subprocess.py:93} INFO - 2025-06-08 13:38:20,211 - ERROR - Connect attempt to <BrokerConnection node_id=bootstrap-0 host=localhost:9092 <connecting> [IPv6 ('::1', 9092, 0, 0)]> returned error 111. Disconnecting.
[2025-06-08T13:38:20.214+0000] {subprocess.py:93} INFO - 2025-06-08 13:38:20,211 - ERROR - <BrokerConnection node_id=bootstrap-0 host=localhost:9092 <connecting> [IPv6 ('::1', 9092, 0, 0)]>: Closing connection. KafkaConnectionError: 111 ECONNREFUSED
[2025-06-08T13:38:20.260+0000] {subprocess.py:93} INFO - 2025-06-08 13:38:20,260 - INFO - <BrokerConnection node_id=bootstrap-0 host=localhost:9092 <connecting> [IPv6 ('::1', 9092, 0, 0)]>: connecting to localhost:9092 [('::1', 9092, 0, 0) IPv6]
[2025-06-08T13:38:20.260+0000] {subprocess.py:93} INFO - 2025-06-08 13:38:20,260 - ERROR - Connect attempt to <BrokerConnection node_id=bootstrap-0 host=localhost:9092 <connecting> [IPv6 ('::1', 9092, 0, 0)]> returned error 111. Disconnecting.
[2025-06-08T13:38:20.261+0000] {subprocess.py:93} INFO - 2025-06-08 13:38:20,260 - ERROR - <BrokerConnection node_id=bootstrap-0 host=localhost:9092 <connecting> [IPv6 ('::1', 9092, 0, 0)]>: Closing connection. KafkaConnectionError: 111 ECONNREFUSED
[2025-06-08T13:38:20.310+0000] {subprocess.py:93} INFO - 2025-06-08 13:38:20,310 - INFO - <BrokerConnection node_id=bootstrap-0 host=localhost:9092 <connecting> [IPv4 ('127.0.0.1', 9092)]>: connecting to localhost:9092 [('127.0.0.1', 9092) IPv4]
[2025-06-08T13:38:20.311+0000] {subprocess.py:93} INFO - 2025-06-08 13:38:20,310 - ERROR - Connect attempt to <BrokerConnection node_id=bootstrap-0 host=localhost:9092 <connecting> [IPv4 ('127.0.0.1', 9092)]> returned error 111. Disconnecting.
[2025-06-08T13:38:20.311+0000] {subprocess.py:93} INFO - 2025-06-08 13:38:20,311 - ERROR - <BrokerConnection node_id=bootstrap-0 host=localhost:9092 <connecting> [IPv4 ('127.0.0.1', 9092)]>: Closing connection. KafkaConnectionError: 111 ECONNREFUSED
[2025-06-08T13:38:20.311+0000] {subprocess.py:93} INFO - Traceback (most recent call last):
[2025-06-08T13:38:20.311+0000] {subprocess.py:93} INFO -   File "/opt/***/kafka_client/consumer.py", line 73, in <module>
[2025-06-08T13:38:20.312+0000] {subprocess.py:93} INFO -     consumer = KafkaConsumer(
[2025-06-08T13:38:20.315+0000] {subprocess.py:93} INFO -                ^^^^^^^^^^^^^^
[2025-06-08T13:38:20.315+0000] {subprocess.py:93} INFO -   File "/home/***/.local/lib/python3.12/site-packages/kafka/consumer/group.py", line 358, in __init__
[2025-06-08T13:38:20.315+0000] {subprocess.py:93} INFO -     self._client = self.config['kafka_client'](metrics=self._metrics, **self.config)
[2025-06-08T13:38:20.316+0000] {subprocess.py:93} INFO -                    ^^^^^^^^^^^^^^^^^^^^^^^^^^^^^^^^^^^^^^^^^^^^^^^^^^^^^^^^^^^^^^^^^
[2025-06-08T13:38:20.316+0000] {subprocess.py:93} INFO -   File "/home/***/.local/lib/python3.12/site-packages/kafka/client_async.py", line 244, in __init__
[2025-06-08T13:38:20.316+0000] {subprocess.py:93} INFO -     self.config['api_version'] = self.check_version(timeout=check_timeout)
[2025-06-08T13:38:20.316+0000] {subprocess.py:93} INFO -                                  ^^^^^^^^^^^^^^^^^^^^^^^^^^^^^^^^^^^^^^^^^
[2025-06-08T13:38:20.316+0000] {subprocess.py:93} INFO -   File "/home/***/.local/lib/python3.12/site-packages/kafka/client_async.py", line 900, in check_version
[2025-06-08T13:38:20.316+0000] {subprocess.py:93} INFO -     raise Errors.NoBrokersAvailable()
[2025-06-08T13:38:20.316+0000] {subprocess.py:93} INFO - kafka.errors.NoBrokersAvailable: NoBrokersAvailable
[2025-06-08T13:38:20.437+0000] {subprocess.py:97} INFO - Command exited with return code 1
[2025-06-08T13:38:20.438+0000] {taskinstance.py:441} INFO - ::group::Post task execution logs
[2025-06-08T13:38:20.444+0000] {taskinstance.py:2905} ERROR - Task failed with exception
Traceback (most recent call last):
  File "/home/airflow/.local/lib/python3.12/site-packages/airflow/models/taskinstance.py", line 465, in _execute_task
    result = _execute_callable(context=context, **execute_callable_kwargs)
             ^^^^^^^^^^^^^^^^^^^^^^^^^^^^^^^^^^^^^^^^^^^^^^^^^^^^^^^^^^^^^
  File "/home/airflow/.local/lib/python3.12/site-packages/airflow/models/taskinstance.py", line 432, in _execute_callable
    return execute_callable(context=context, **execute_callable_kwargs)
           ^^^^^^^^^^^^^^^^^^^^^^^^^^^^^^^^^^^^^^^^^^^^^^^^^^^^^^^^^^^^
  File "/home/airflow/.local/lib/python3.12/site-packages/airflow/models/baseoperator.py", line 400, in wrapper
    return func(self, *args, **kwargs)
           ^^^^^^^^^^^^^^^^^^^^^^^^^^^
  File "/home/airflow/.local/lib/python3.12/site-packages/airflow/operators/bash.py", line 243, in execute
    raise AirflowException(
airflow.exceptions.AirflowException: Bash command failed. The command returned a non-zero exit code 1.
[2025-06-08T13:38:20.447+0000] {taskinstance.py:1206} INFO - Marking task as FAILED. dag_id=master_pipeline_with_es_guard, task_id=run_consumer, run_id=manual__2025-06-08T13:37:49.721097+00:00, execution_date=20250608T133749, start_date=20250608T133818, end_date=20250608T133820
[2025-06-08T13:38:20.454+0000] {standard_task_runner.py:110} ERROR - Failed to execute job 35 for task run_consumer (Bash command failed. The command returned a non-zero exit code 1.; 1454)
[2025-06-08T13:38:20.491+0000] {local_task_job_runner.py:240} INFO - Task exited with return code 1
[2025-06-08T13:38:20.504+0000] {taskinstance.py:3498} INFO - 0 downstream tasks scheduled from follow-on schedule check
[2025-06-08T13:38:20.506+0000] {local_task_job_runner.py:222} INFO - ::endgroup::
