[2025-06-08T13:30:19.463+0000] {local_task_job_runner.py:120} INFO - ::group::Pre task execution logs
[2025-06-08T13:30:19.496+0000] {taskinstance.py:2076} INFO - Dependencies all met for dep_context=non-requeueable deps ti=<TaskInstance: master_pipeline_with_es_guard.run_consumer scheduled__2025-06-08T13:00:00+00:00 [queued]>
[2025-06-08T13:30:19.503+0000] {taskinstance.py:2076} INFO - Dependencies all met for dep_context=requeueable deps ti=<TaskInstance: master_pipeline_with_es_guard.run_consumer scheduled__2025-06-08T13:00:00+00:00 [queued]>
[2025-06-08T13:30:19.503+0000] {taskinstance.py:2306} INFO - Starting attempt 2 of 2
[2025-06-08T13:30:19.515+0000] {taskinstance.py:2330} INFO - Executing <Task(BashOperator): run_consumer> on 2025-06-08 13:00:00+00:00
[2025-06-08T13:30:19.521+0000] {standard_task_runner.py:90} INFO - Running: ['***', 'tasks', 'run', 'master_pipeline_with_es_guard', 'run_consumer', 'scheduled__2025-06-08T13:00:00+00:00', '--job-id', '31', '--raw', '--subdir', 'DAGS_FOLDER/producer_dag.py', '--cfg-path', '/tmp/tmpvw2j61cd']
[2025-06-08T13:30:19.524+0000] {standard_task_runner.py:91} INFO - Job 31: Subtask run_consumer
[2025-06-08T13:30:19.523+0000] {logging_mixin.py:188} WARNING - /home/***/.local/lib/python3.12/site-packages/***/task/task_runner/standard_task_runner.py:61 DeprecationWarning: This process (pid=1146) is multi-threaded, use of fork() may lead to deadlocks in the child.
[2025-06-08T13:30:19.524+0000] {standard_task_runner.py:63} INFO - Started process 1147 to run task
[2025-06-08T13:30:19.568+0000] {task_command.py:426} INFO - Running <TaskInstance: master_pipeline_with_es_guard.run_consumer scheduled__2025-06-08T13:00:00+00:00 [running]> on host 5492e8ecb5c1
[2025-06-08T13:30:19.641+0000] {taskinstance.py:2648} INFO - Exporting env vars: AIRFLOW_CTX_DAG_OWNER='panshul' AIRFLOW_CTX_DAG_ID='master_pipeline_with_es_guard' AIRFLOW_CTX_TASK_ID='run_consumer' AIRFLOW_CTX_EXECUTION_DATE='2025-06-08T13:00:00+00:00' AIRFLOW_CTX_TRY_NUMBER='2' AIRFLOW_CTX_DAG_RUN_ID='scheduled__2025-06-08T13:00:00+00:00'
[2025-06-08T13:30:19.642+0000] {taskinstance.py:430} INFO - ::endgroup::
[2025-06-08T13:30:19.654+0000] {subprocess.py:63} INFO - Tmp dir root location: /tmp
[2025-06-08T13:30:19.655+0000] {subprocess.py:75} INFO - Running command: ['/usr/bin/bash', '-c', 'python /opt/***/kafka_client/consumer.py']
[2025-06-08T13:30:19.661+0000] {subprocess.py:86} INFO - Output:
[2025-06-08T13:30:20.842+0000] {subprocess.py:93} INFO - Traceback (most recent call last):
[2025-06-08T13:30:20.842+0000] {subprocess.py:93} INFO -   File "/opt/***/kafka_client/consumer.py", line 13, in <module>
[2025-06-08T13:30:20.842+0000] {subprocess.py:93} INFO -     from transformer import transform_record
[2025-06-08T13:30:20.845+0000] {subprocess.py:93} INFO -   File "/opt/***/kafka_client/../transforms/transformer.py", line 7, in <module>
[2025-06-08T13:30:20.846+0000] {subprocess.py:93} INFO -     from geotext import GeoText
[2025-06-08T13:30:20.848+0000] {subprocess.py:93} INFO - ModuleNotFoundError: No module named 'geotext'
[2025-06-08T13:30:20.935+0000] {subprocess.py:97} INFO - Command exited with return code 1
[2025-06-08T13:30:20.936+0000] {taskinstance.py:441} INFO - ::group::Post task execution logs
[2025-06-08T13:30:20.943+0000] {taskinstance.py:2905} ERROR - Task failed with exception
Traceback (most recent call last):
  File "/home/airflow/.local/lib/python3.12/site-packages/airflow/models/taskinstance.py", line 465, in _execute_task
    result = _execute_callable(context=context, **execute_callable_kwargs)
             ^^^^^^^^^^^^^^^^^^^^^^^^^^^^^^^^^^^^^^^^^^^^^^^^^^^^^^^^^^^^^
  File "/home/airflow/.local/lib/python3.12/site-packages/airflow/models/taskinstance.py", line 432, in _execute_callable
    return execute_callable(context=context, **execute_callable_kwargs)
           ^^^^^^^^^^^^^^^^^^^^^^^^^^^^^^^^^^^^^^^^^^^^^^^^^^^^^^^^^^^^
  File "/home/airflow/.local/lib/python3.12/site-packages/airflow/models/baseoperator.py", line 400, in wrapper
    return func(self, *args, **kwargs)
           ^^^^^^^^^^^^^^^^^^^^^^^^^^^
  File "/home/airflow/.local/lib/python3.12/site-packages/airflow/operators/bash.py", line 243, in execute
    raise AirflowException(
airflow.exceptions.AirflowException: Bash command failed. The command returned a non-zero exit code 1.
[2025-06-08T13:30:20.945+0000] {taskinstance.py:1206} INFO - Marking task as FAILED. dag_id=master_pipeline_with_es_guard, task_id=run_consumer, run_id=scheduled__2025-06-08T13:00:00+00:00, execution_date=20250608T130000, start_date=20250608T133019, end_date=20250608T133020
[2025-06-08T13:30:20.953+0000] {standard_task_runner.py:110} ERROR - Failed to execute job 31 for task run_consumer (Bash command failed. The command returned a non-zero exit code 1.; 1147)
[2025-06-08T13:30:20.978+0000] {local_task_job_runner.py:240} INFO - Task exited with return code 1
[2025-06-08T13:30:20.991+0000] {taskinstance.py:3498} INFO - 0 downstream tasks scheduled from follow-on schedule check
[2025-06-08T13:30:20.993+0000] {local_task_job_runner.py:222} INFO - ::endgroup::
