[2025-06-08T13:30:02.330+0000] {local_task_job_runner.py:120} INFO - ::group::Pre task execution logs
[2025-06-08T13:30:02.346+0000] {taskinstance.py:2076} INFO - Dependencies all met for dep_context=non-requeueable deps ti=<TaskInstance: master_pipeline_with_es_guard.run_consumer scheduled__2025-06-08T13:00:00+00:00 [queued]>
[2025-06-08T13:30:02.350+0000] {taskinstance.py:2076} INFO - Dependencies all met for dep_context=requeueable deps ti=<TaskInstance: master_pipeline_with_es_guard.run_consumer scheduled__2025-06-08T13:00:00+00:00 [queued]>
[2025-06-08T13:30:02.351+0000] {taskinstance.py:2306} INFO - Starting attempt 1 of 2
[2025-06-08T13:30:02.358+0000] {taskinstance.py:2330} INFO - Executing <Task(BashOperator): run_consumer> on 2025-06-08 13:00:00+00:00
[2025-06-08T13:30:02.362+0000] {standard_task_runner.py:90} INFO - Running: ['***', 'tasks', 'run', 'master_pipeline_with_es_guard', 'run_consumer', 'scheduled__2025-06-08T13:00:00+00:00', '--job-id', '30', '--raw', '--subdir', 'DAGS_FOLDER/producer_dag.py', '--cfg-path', '/tmp/tmphxl3dgdp']
[2025-06-08T13:30:02.363+0000] {standard_task_runner.py:91} INFO - Job 30: Subtask run_consumer
[2025-06-08T13:30:02.363+0000] {logging_mixin.py:188} WARNING - /home/***/.local/lib/python3.12/site-packages/***/task/task_runner/standard_task_runner.py:61 DeprecationWarning: This process (pid=1131) is multi-threaded, use of fork() may lead to deadlocks in the child.
[2025-06-08T13:30:02.364+0000] {standard_task_runner.py:63} INFO - Started process 1132 to run task
[2025-06-08T13:30:02.387+0000] {task_command.py:426} INFO - Running <TaskInstance: master_pipeline_with_es_guard.run_consumer scheduled__2025-06-08T13:00:00+00:00 [running]> on host 5492e8ecb5c1
[2025-06-08T13:30:02.427+0000] {taskinstance.py:2648} INFO - Exporting env vars: AIRFLOW_CTX_DAG_OWNER='panshul' AIRFLOW_CTX_DAG_ID='master_pipeline_with_es_guard' AIRFLOW_CTX_TASK_ID='run_consumer' AIRFLOW_CTX_EXECUTION_DATE='2025-06-08T13:00:00+00:00' AIRFLOW_CTX_TRY_NUMBER='1' AIRFLOW_CTX_DAG_RUN_ID='scheduled__2025-06-08T13:00:00+00:00'
[2025-06-08T13:30:02.428+0000] {taskinstance.py:430} INFO - ::endgroup::
[2025-06-08T13:30:02.435+0000] {subprocess.py:63} INFO - Tmp dir root location: /tmp
[2025-06-08T13:30:02.435+0000] {subprocess.py:75} INFO - Running command: ['/usr/bin/bash', '-c', 'python /opt/***/kafka_client/consumer.py']
[2025-06-08T13:30:02.440+0000] {subprocess.py:86} INFO - Output:
[2025-06-08T13:30:03.765+0000] {subprocess.py:93} INFO - Traceback (most recent call last):
[2025-06-08T13:30:03.766+0000] {subprocess.py:93} INFO -   File "/opt/***/kafka_client/consumer.py", line 13, in <module>
[2025-06-08T13:30:03.766+0000] {subprocess.py:93} INFO -     from transformer import transform_record
[2025-06-08T13:30:03.766+0000] {subprocess.py:93} INFO -   File "/opt/***/kafka_client/../transforms/transformer.py", line 7, in <module>
[2025-06-08T13:30:03.766+0000] {subprocess.py:93} INFO -     from geotext import GeoText
[2025-06-08T13:30:03.767+0000] {subprocess.py:93} INFO - ModuleNotFoundError: No module named 'geotext'
[2025-06-08T13:30:03.891+0000] {subprocess.py:97} INFO - Command exited with return code 1
[2025-06-08T13:30:03.892+0000] {taskinstance.py:441} INFO - ::group::Post task execution logs
[2025-06-08T13:30:03.900+0000] {taskinstance.py:2905} ERROR - Task failed with exception
Traceback (most recent call last):
  File "/home/airflow/.local/lib/python3.12/site-packages/airflow/models/taskinstance.py", line 465, in _execute_task
    result = _execute_callable(context=context, **execute_callable_kwargs)
             ^^^^^^^^^^^^^^^^^^^^^^^^^^^^^^^^^^^^^^^^^^^^^^^^^^^^^^^^^^^^^
  File "/home/airflow/.local/lib/python3.12/site-packages/airflow/models/taskinstance.py", line 432, in _execute_callable
    return execute_callable(context=context, **execute_callable_kwargs)
           ^^^^^^^^^^^^^^^^^^^^^^^^^^^^^^^^^^^^^^^^^^^^^^^^^^^^^^^^^^^^
  File "/home/airflow/.local/lib/python3.12/site-packages/airflow/models/baseoperator.py", line 400, in wrapper
    return func(self, *args, **kwargs)
           ^^^^^^^^^^^^^^^^^^^^^^^^^^^
  File "/home/airflow/.local/lib/python3.12/site-packages/airflow/operators/bash.py", line 243, in execute
    raise AirflowException(
airflow.exceptions.AirflowException: Bash command failed. The command returned a non-zero exit code 1.
[2025-06-08T13:30:03.904+0000] {taskinstance.py:1206} INFO - Marking task as UP_FOR_RETRY. dag_id=master_pipeline_with_es_guard, task_id=run_consumer, run_id=scheduled__2025-06-08T13:00:00+00:00, execution_date=20250608T130000, start_date=20250608T133002, end_date=20250608T133003
[2025-06-08T13:30:03.915+0000] {standard_task_runner.py:110} ERROR - Failed to execute job 30 for task run_consumer (Bash command failed. The command returned a non-zero exit code 1.; 1132)
[2025-06-08T13:30:03.939+0000] {local_task_job_runner.py:240} INFO - Task exited with return code 1
[2025-06-08T13:30:03.956+0000] {taskinstance.py:3498} INFO - 0 downstream tasks scheduled from follow-on schedule check
[2025-06-08T13:30:03.957+0000] {local_task_job_runner.py:222} INFO - ::endgroup::
