[2025-06-10T12:34:31.980+0000] {local_task_job_runner.py:120} INFO - ::group::Pre task execution logs
[2025-06-10T12:34:32.007+0000] {taskinstance.py:2076} INFO - Dependencies all met for dep_context=non-requeueable deps ti=<TaskInstance: kafka_pipeline_branching_dag.run_consumer manual__2025-06-10T12:29:18.091636+00:00 [queued]>
[2025-06-10T12:34:32.014+0000] {taskinstance.py:2076} INFO - Dependencies all met for dep_context=requeueable deps ti=<TaskInstance: kafka_pipeline_branching_dag.run_consumer manual__2025-06-10T12:29:18.091636+00:00 [queued]>
[2025-06-10T12:34:32.014+0000] {taskinstance.py:2306} INFO - Starting attempt 2 of 3
[2025-06-10T12:34:32.026+0000] {taskinstance.py:2330} INFO - Executing <Task(BashOperator): run_consumer> on 2025-06-10 12:29:18.091636+00:00
[2025-06-10T12:34:32.032+0000] {logging_mixin.py:188} WARNING - /home/***/.local/lib/python3.12/site-packages/***/task/task_runner/standard_task_runner.py:61 DeprecationWarning: This process (pid=10386) is multi-threaded, use of fork() may lead to deadlocks in the child.
[2025-06-10T12:34:32.033+0000] {standard_task_runner.py:63} INFO - Started process 10387 to run task
[2025-06-10T12:34:32.033+0000] {standard_task_runner.py:90} INFO - Running: ['***', 'tasks', 'run', 'kafka_pipeline_branching_dag', 'run_consumer', 'manual__2025-06-10T12:29:18.091636+00:00', '--job-id', '34', '--raw', '--subdir', 'DAGS_FOLDER/kafka_pipeline_dag.py', '--cfg-path', '/tmp/tmp_dml_zw8']
[2025-06-10T12:34:32.035+0000] {standard_task_runner.py:91} INFO - Job 34: Subtask run_consumer
[2025-06-10T12:34:32.080+0000] {task_command.py:426} INFO - Running <TaskInstance: kafka_pipeline_branching_dag.run_consumer manual__2025-06-10T12:29:18.091636+00:00 [running]> on host 4e91ff50f4f4
[2025-06-10T12:34:32.150+0000] {taskinstance.py:2648} INFO - Exporting env vars: AIRFLOW_CTX_DAG_OWNER='***' AIRFLOW_CTX_DAG_ID='kafka_pipeline_branching_dag' AIRFLOW_CTX_TASK_ID='run_consumer' AIRFLOW_CTX_EXECUTION_DATE='2025-06-10T12:29:18.091636+00:00' AIRFLOW_CTX_TRY_NUMBER='2' AIRFLOW_CTX_DAG_RUN_ID='manual__2025-06-10T12:29:18.091636+00:00'
[2025-06-10T12:34:32.150+0000] {taskinstance.py:430} INFO - ::endgroup::
[2025-06-10T12:34:32.158+0000] {subprocess.py:63} INFO - Tmp dir root location: /tmp
[2025-06-10T12:34:32.159+0000] {subprocess.py:75} INFO - Running command: ['/usr/bin/bash', '-c', 'timeout 300 python /opt/***/kafka_client/consumer.py > /opt/***/logs/consumer_output.log 2>&1']
[2025-06-10T12:34:32.168+0000] {subprocess.py:86} INFO - Output:
[2025-06-10T12:39:32.179+0000] {subprocess.py:97} INFO - Command exited with return code 124
[2025-06-10T12:39:32.187+0000] {taskinstance.py:441} INFO - ::group::Post task execution logs
[2025-06-10T12:39:32.217+0000] {taskinstance.py:2905} ERROR - Task failed with exception
Traceback (most recent call last):
  File "/home/airflow/.local/lib/python3.12/site-packages/airflow/models/taskinstance.py", line 465, in _execute_task
    result = _execute_callable(context=context, **execute_callable_kwargs)
             ^^^^^^^^^^^^^^^^^^^^^^^^^^^^^^^^^^^^^^^^^^^^^^^^^^^^^^^^^^^^^
  File "/home/airflow/.local/lib/python3.12/site-packages/airflow/models/taskinstance.py", line 432, in _execute_callable
    return execute_callable(context=context, **execute_callable_kwargs)
           ^^^^^^^^^^^^^^^^^^^^^^^^^^^^^^^^^^^^^^^^^^^^^^^^^^^^^^^^^^^^
  File "/home/airflow/.local/lib/python3.12/site-packages/airflow/models/baseoperator.py", line 400, in wrapper
    return func(self, *args, **kwargs)
           ^^^^^^^^^^^^^^^^^^^^^^^^^^^
  File "/home/airflow/.local/lib/python3.12/site-packages/airflow/operators/bash.py", line 243, in execute
    raise AirflowException(
airflow.exceptions.AirflowException: Bash command failed. The command returned a non-zero exit code 124.
[2025-06-10T12:39:32.227+0000] {taskinstance.py:1206} INFO - Marking task as UP_FOR_RETRY. dag_id=kafka_pipeline_branching_dag, task_id=run_consumer, run_id=manual__2025-06-10T12:29:18.091636+00:00, execution_date=20250610T122918, start_date=20250610T123432, end_date=20250610T123932
[2025-06-10T12:39:32.242+0000] {standard_task_runner.py:110} ERROR - Failed to execute job 34 for task run_consumer (Bash command failed. The command returned a non-zero exit code 124.; 10387)
[2025-06-10T12:39:32.261+0000] {local_task_job_runner.py:240} INFO - Task exited with return code 1
[2025-06-10T12:39:32.284+0000] {taskinstance.py:3498} INFO - 0 downstream tasks scheduled from follow-on schedule check
[2025-06-10T12:39:32.285+0000] {local_task_job_runner.py:222} INFO - ::endgroup::
